Workbook

Sheet Site Selector Data - edited
A1: Account Weights | H1: City Assignments
A2: Hydrological & Regulatory Risk | B2: Climate & Operational Physics | C2: Economic & Social Impact | D2: Natural Hazards | E2: Biodiversity | H2: 1 | I2: 2 | J2: 3 | K2: 4 | L2: 5
A3: 0.25 | B3: 0.3 | C3: 0.15 | D3: 0.2 | E3: 0.1 | H3: Oklahoma City | I3: Boston | J3: Denver | K3: Houston | L3: Gainesville
A5: Account | B5: Sub-Account | C5: Description | D5: Unit | E5: City | F5: Value | G5: Score | H5: Source | I5: Notes | J5: Scoring Criteria
A6: Hydrological & Regulatory Risk | B6: Baseline Water Stress (Regional) | C6: Regional water withdrawal to availability ratio (WRI framework) | D6: Category | E6: 1 | F6: Low-Medium | G6: 4 | H6: https://www.wri.org/applications/aqueduct/water-risk-atlas/ | I6: Aqueduct tool created by the WRI, helps quantify overall water risk. | J6: 5 | K6: low
E7: 2 | F7: Low-Medium | G7: 4 | H7: https://www.wri.org/applications/aqueduct/water-risk-atlas/ | J7: 4 | K7: low-medium
E8: 3 | F8: High | G8: 1 | H8: https://www.wri.org/applications/aqueduct/water-risk-atlas/ | J8: 3 | K8: medium
E9: 4 | F9: Low-Medium | G9: 4 | H9: https://www.wri.org/applications/aqueduct/water-risk-atlas/ | J9: 2 | K9: medium-high
E10: 5 | F10: Medium | G10: 3 | H10: https://www.wri.org/applications/aqueduct/water-risk-atlas/ | J10: 1 | K10: high
A11: Hydrological & Regulatory Risk | B11: Annual Precipitation (1991-2020) | C11: NOAA 30-year climate normal total precipitation | D11: inches | E11: 1 | F11: 36.95 | G11: 1 | H11: https://www.ncei.noaa.gov/products/land-based-station/us-climate-normals | I11: Used quick access tool for each city. Used 30-yr average (1991-2020) to get best average data. Did not use seasonal data. If multiple stations were available, the one used is marked in a note. Snow precipitation was included when available. | J11: 5 | K11: wettest
E12: 2 | F12: 92.79 | G12: 5 | H12: https://www.ncei.noaa.gov/products/land-based-station/us-climate-normals | J12: 4
E13: 3 | F13: 56.55 | G13: 4 | H13: https://www.ncei.noaa.gov/products/land-based-station/us-climate-normals | J13: 3
E14: 4 | F14: 54.12 | G14: 3 | H14: https://www.ncei.noaa.gov/products/land-based-station/us-climate-normals | J14: 2
E15: 5 | F15: 48.31 | G15: 2 | H15: https://www.ncei.noaa.gov/products/land-based-station/us-climate-normals | J15: 1 | K15: dryest
A16: Hydrological & Regulatory Risk | B16: Recycled Water Infrastructure | C16: Industrial reclaimed water programs operational | D16: Yes/No | E16: 1 | F16: Yes | G16: 5 | H16: https://oklahoma.gov/content/dam/ok/en/owrb/documents/water-planning/technical-reports/owrap-fact-sheet.pdf#:~:text=The%20overarching%20goal%20of%20the%20OWRAP%20is,water%20users%20(municipal%2C%20agricultural%2C%20industrial%2C%20and%20others). | I16: City reclaimed water programs, when available. Simple yes or no to if the program exists. Developer must do further research if interested in this parameter. | J16: 5 | K16: Yes
E17: 2 | F17: Yes | G17: 5 | H17: https://www.mass.gov/info-details/wastewater-reclaimed-water | J17: 1 | K17: No
E18: 3 | F18: Yes | G18: 5 | H18: https://cwcb.colorado.gov/focus-areas/supply/water-reuse
E19: 4 | F19: Yes | G19: 5 | H19: https://www.twdb.texas.gov/innovativewater/reuse/index.asp
E20: 5 | F20: Yes | G20: 5 | H20: https://floridadep.gov/water/domestic-wastewater/content/water-reuse-program
A21: Climate & Operational Physics | B21: Cooling Degree Days (1991-2020) | C21: Annual cooling demand indicator (base 65°F) | D21: CDD | E21: 1 | F21: 1975 | G21: 3 | H21: https://www.ncei.noaa.gov/products/land-based-station/us-climate-normals | I21: Same tool from precipitation is linked. CDD is calculated as the difference between the temp (above 65) and 65. Used average temperatures taken from the website listed. | J21: 5 | K21: lowest
E22: 2 | F22: 665 | G22: 5 | H22: https://www.ncei.noaa.gov/products/land-based-station/us-climate-normals | J22: 4
E23: 3 | F23: 698 | G23: 4 | H23: https://www.ncei.noaa.gov/products/land-based-station/us-climate-normals | J23: 3
E24: 4 | F24: 3042 | G24: 1 | H24: https://www.ncei.noaa.gov/products/land-based-station/us-climate-normals | J24: 2
E25: 5 | F25: 2486 | G25: 2 | H25: https://www.ncei.noaa.gov/products/land-based-station/us-climate-normals | J25: 1 | K25: highest
A26: Climate & Operational Physics | B26: Annual Mean Relative Humidity | C26: Average RH affects evaporative cooling efficiency | D26: % | E26: 1 | F26: 80 | G26: 3 | H26: https://www.ncei.noaa.gov/products/land-based-station/comparative-climatic-data | I26: Used the annual values at the end of the text file table. Used the higher value, usually in the morning. Not all values are from the same date range. | J26: 5 | K26: lowest
E27: 2 | F27: 72 | G27: 4 | H27: https://www.ncei.noaa.gov/products/land-based-station/comparative-climatic-data | J27: 4
E28: 3 | F28: 50 | G28: 5 | H28: https://www.ncei.noaa.gov/products/land-based-station/comparative-climatic-data | J28: 3
E29: 4 | F29: 89 | G29: 2 | H29: https://www.ncei.noaa.gov/products/land-based-station/comparative-climatic-data | J29: 2
E30: 5 | F30: 89 | G30: 2 | H30: https://www.ncei.noaa.gov/products/land-based-station/comparative-climatic-data | J30: 1 | K30: highest
A31: Climate & Operational Physics | B31: Carbon Regulations | C31: State regulations on carbon emissions | D31: Category | E31: 1 | F31: Low | G31: 5 | H31: https://oklahoma.gov/deq/divisions/air-quality/rules-planning.html | I31: Linked each states carbon emission regulation pages, specifically for the energy industry when available. Ranked on how strict the regualations were compared to the standard EPA regulations. | J31: 5 | K31: low
E32: 2 | F32: Medium-high | G32: 2 | H32: https://www.boston.gov/departments/environment/berdo | J32: 4 | K32: medium-low
E33: 3 | F33: High | G33: 1 | H33: https://www.denvergov.org/Government/Agencies-Departments-Offices/Agencies-Departments-Offices-Directory/Climate-Action-Sustainability-and-Resiliency/Cutting-Denvers-Carbon-Pollution/Efficient-Buildings-and-Homes/Denver-Building-Regulations | J33: 3 | K33: medium
E34: 4 | F34: Medium-high | G34: 2 | H34: https://www.houstontx.gov/policies/adminpolicies/3-40.pdf | J34: 2 | K34: medium-high
E35: 5 | F35: Medium | G35: 3 | H35: https://www.epa.gov/egrid (FL: 786.6 lb/MWh) | J35: 1 | K35: high
A36: Climate & Operational Physics | B36: Renewable Energy Mix | C36: State renewable generation percentage (wind+solar+hydro) | D36: % | E36: 1 | F36: 43.6 | G36: 5 | H36: https://www.epa.gov/egrid (OK: 41.6% wind+solar+hydro) | I36: Adding wind, solar, and hydro, biomass, and geothermal fuels to show total renewable energy. Coming from egrit map, resource mix for total generation, for all fuels at the state level, 2023. Using percentage of state resources, not US resources. | J36: 5 | K36: highest
E37: 2 | F37: 19.6 | G37: 2 | H37: https://www.epa.gov/egrid (MA: 18.7% wind+solar+hydro) | J37: 4
E38: 3 | F38: 37.3 | G38: 4 | H38: https://www.epa.gov/egrid (CO: 34.5% wind+solar+hydro) | J38: 3
E39: 4 | F39: 27.3 | G39: 3 | H39: https://www.epa.gov/egrid (TX: 26.1% wind+solar+hydro) | J39: 2
E40: 5 | F40: 6.7 | G40: 1 | H40: https://www.epa.gov/egrid (FL: 6.7% wind+solar+hydro) | J40: 1 | K40: lowest
A41: Economic & Social Impact | B41: Industrial Electricity Rate (2024) | C41: Average industrial electric rate (EIA official data) | D41: ¢/kWh | E41: 1 | F41: 5.84 | G41: 5 | H41: https://www.eia.gov/electricity/sales_revenue_price/ (OK: 5.84¢/kWh) | I41: Using Summary Table T5.c pdf | J41: 5 | K41: lowest
...

Sheet City Assignments
A1: City | B1: Code
A2: Oklahoma City | B2: 1
A3: Boston | B3: 2
A4: Denver | B4: 3
A5: Houston | B5: 4
A6: Gainesville | B6: 5

Sheet Accounts
A1: Account | B1: Sub-Account | C1: Description
A2: Hydrological & Regulatory Risk | B2: Baseline Water Stress (Regional) | C2: Regional water withdrawal to availability ratio (WRI framework)
A3: Hydrological & Regulatory Risk | B3: Annual Precipitation (1991-2020) | C3: NOAA 30-year climate normal total precipitation
A4: Hydrological & Regulatory Risk | B4: Recycled Water Infrastructure | C4: Industrial reclaimed water programs operational
A5: Climate & Operational Physics | B5: Cooling Degree Days (1991-2020) | C5: Annual cooling demand indicator (base 65°F)
A6: Climate & Operational Physics | B6: Annual Mean Relative Humidity | C6: Average RH affects evaporative cooling efficiency
A7: Climate & Operational Physics | B7: Carbon Regulations | C7: State regulations on carbon emissions
A8: Climate & Operational Physics | B8: Renewable Energy Mix | C8: State renewable generation percentage (wind+solar+hydro)
A9: Economic & Social Impact | B9: Industrial Electricity Rate (2024) | C9: Average industrial electric rate (EIA official data)
A10: Economic & Social Impact | B10: Water & Sewer Cost (Industrial) | C10: Combined water/sewer cost for large users
A11: Economic & Social Impact | B11: Environmental Justice Index | C11: EPA EJScreen regional environmental burden percentile
A12: Natural Hazards | B12: Seismic Hazard (USGS 2023) | C12: Seismic Design Category (A is low F is high)
... A17: Biodiversity | B17: Protected Area Proximity | C17: Distance to nearest NPS/critical habitat

Sheet Values
A1: City | B1: Name | C1: Baseline Water Stress (Regional) | D1: Annual Precipitation (1991-2020) | E1: Recycled Water Infrastructure | F1: Cooling Degree Days (1991-2020) | G1: Annual Mean Relative Humidity | H1: Carbon Regulations | I1: Renewable Energy Mix | J1: Industrial Electricity Rate (2024) | K1: Water & Sewer Cost (Industrial) | L1: Environmental Justice Index | M1: Seismic Hazard (USGS 2023) | N1: Flood Risk Zone | O1: Tornado Frequency (Annual Avg) | P1: Wildfire Hazard | Q1: Winter Weather Disruption | R1: Protected Area Proximity
C2: Category | D2: inches | E2: Yes/No | F2: CDD | G2: % | H2: Category | I2: % | J2: ¢/kWh | K2: $/1000gal | L2: Percentile | M2: Category | N2: Risk Level | O2: events/yr | P2: Risk Level | Q2: Risk Level | R2: Miles
A3: 1 | B3: Oklahoma City | C3: ='Site Selector Data - edited'!F6 -> Low-Medium | D3: ='Site Selector Data - edited'!F11 -> 36.95 | E3: ='Site Selector Data - edited'!F16 -> Yes | F3: ='Site Selector Data - edited'!F21 -> 1975 | G3: ='Site Selector Data - edited'!F26 -> 80 | H3: ='Site Selector Data - edited'!F31 -> Low | I3: ='Site Selector Data - edited'!F36 -> 43.6 | J3: ='Site Selector Data - edited'!F41 -> 5.84 | K3: ='Site Selector Data - edited'!F46 -> 6.52 | L3: ='Site Selector Data - edited'!F51 -> 90 | M3: ='Site Selector Data - edited'!F56 -> C | N3: ='Site Selector Data - edited'!F61 -> Medium-high | O3: ='Site Selector Data - edited'!F66 -> 59 | P3: ='Site Selector Data - edited'!F71 -> Moderate | Q3: ='Site Selector Data - edited'!F76 -> Low | R3: ='Site Selector Data - edited'!F81 -> 18
A4: 2 | B4: Boston | C4: ='Site Selector Data - edited'!F7 -> Low-Medium | D4: ='Site Selector Data - edited'!F12 -> 92.79 | E4: ='Site Selector Data - edited'!F17 -> Yes | F4: ='Site Selector Data - edited'!F22 -> 665 | G4: ='Site Selector Data - edited'!F27 -> 72 | H4: ='Site Selector Data - edited'!F32 -> Medium-high | I4: ='Site Selector Data - edited'!F37 -> 19.6 | J4: ='Site Selector Data - edited'!F42 -> 18.19 | K4: ='Site Selector Data - edited'!F47 -> 12.76 | L4: ='Site Selector Data - edited'!F52 -> 80 | M4: ='Site Selector Data - edited'!F57 -> C | N4: ='Site Selector Data - edited'!F62 -> Medium | O4: ='Site Selector Data - edited'!F67 -> 0 | P4: ='Site Selector Data - edited'!F72 -> High | Q4: ='Site Selector Data - edited'!F77 -> Moderate | R4: ='Site Selector Data - edited'!F82 -> 5
A5: 3 | B5: Denver | C5: ='Site Selector Data - edited'!F8 -> High | D5: ='Site Selector Data - edited'!F13 -> 56.55 | E5: ='Site Selector Data - edited'!F18 -> Yes | F5: ='Site Selector Data - edited'!F23 -> 698 | G5: ='Site Selector Data - edited'!F28 -> 50 | H5: ='Site Selector Data - edited'!F33 -> High | I5: ='Site Selector Data - edited'!F38 -> 37.3 | J5: ='Site Selector Data - edited'!F43 -> 8.62 | K5: ='Site Selector Data - edited'!F48 -> 5.68 | L5: ='Site Selector Data - edited'!F53 -> 50 | M5: ='Site Selector Data - edited'!F58 -> A | N5: ='Site Selector Data - edited'!F63 -> Medium-high | O5: ='Site Selector Data - edited'!F68 -> 1 | P5: ='Site Selector Data - edited'!F73 -> High | Q5: ='Site Selector Data - edited'!F78 -> Moderate | R5: ='Site Selector Data - edited'!F83 -> 8
A6: 4 | B6: Houston | C6: ='Site Selector Data - edited'!F9 -> Low-Medium | D6: ='Site Selector Data - edited'!F14 -> 54.12 | E6: ='Site Selector Data - edited'!F19 -> Yes | F6: ='Site Selector Data - edited'!F24 -> 3042 | G6: ='Site Selector Data - edited'!F29 -> 89 | H6: ='Site Selector Data - edited'!F34 -> Medium-high | I6: ='Site Selector Data - edited'!F39 -> 27.3 | J6: ='Site Selector Data - edited'!F44 -> 6.12 | K6: ='Site Selector Data - edited'!F49 -> 17.14 | L6: ='Site Selector Data - edited'!F54 -> 95 | M6: ='Site Selector Data - edited'!F59 -> A | N6: ='Site Selector Data - edited'!F64 -> High | O6: ='Site Selector Data - edited'!F69 -> 1 | P6: ='Site Selector Data - edited'!F74 -> Low | Q6: ='Site Selector Data - edited'!F79 -> low | R6: ='Site Selector Data - edited'!F84 -> 22
A7: 5 | B7: Gainesville | C7: ='Site Selector Data - edited'!F10 -> Medium | D7: ='Site Selector Data - edited'!F15 -> 48.31 | E7: ='Site Selector Data - edited'!F20 -> Yes | F7: ='Site Selector Data - edited'!F25 -> 2486 | G7: ='Site Selector Data - edited'!F30 -> 89 | H7: ='Site Selector Data - edited'!F35 -> Medium | I7: ='Site Selector Data - edited'!F40 -> 6.7 | J7: ='Site Selector Data - edited'!F45 -> 8.5 | K7: ='Site Selector Data - edited'!F50 -> 3.72 | L7: ='Site Selector Data - edited'!F55 -> 50 | M7: ='Site Selector Data - edited'!F60 -> C | N7: ='Site Selector Data - edited'!F65 -> Medium | O7: ='Site Selector Data - edited'!F70 -> 1 | P7: ='Site Selector Data - edited'!F75 -> Low | Q7: ='Site Selector Data - edited'!F80 -> low | R7: ='Site Selector Data - edited'!F85 -> 4

Sheet Scores
A1: City | B1: Name | C1: Baseline Water Stress (Regional) | D1: Annual Precipitation (1991-2020) | E1: Recycled Water Infrastructure | F1: Cooling Degree Days (1991-2020) | G1: Annual Mean Relative Humidity | H1: Carbon Regulations | I1: Renewable Energy Mix | J1: Industrial Electricity Rate (2024) | K1: Water & Sewer Cost (Industrial) | L1: Environmental Justice Index | M1: Seismic Hazard (USGS 2023) | N1: Flood Risk Zone | O1: Tornado Frequency (Annual Avg) | P1: Wildfire Hazard | Q1: Winter Weather Disruption | R1: Protected Area Proximity
A2: 1 | B2: Oklahoma City | C2: ='Site Selector Data - edited'!G6 -> 4 | D2: ='Site Selector Data - edited'!G11 -> 1 | E2: ='Site Selector Data - edited'!G16 -> 5 | F2: ='Site Selector Data - edited'!G21 -> 3 | G2: ='Site Selector Data - edited'!G26 -> 3 | H2: ='Site Selector Data - edited'!G31 -> 5 | I2: ='Site Selector Data - edited'!G36 -> 5 | J2: ='Site Selector Data - edited'!G41 -> 5 | K2: ='Site Selector Data - edited'!G46 -> 3 | L2: ='Site Selector Data - edited'!G51 -> 2 | M2: ='Site Selector Data - edited'!G56 -> 3 | N2: ='Site Selector Data - edited'!G61 -> 2 | O2: ='Site Selector Data - edited'!G66 -> 1 | P2: ='Site Selector Data - edited'!G71 -> 3 | Q2: ='Site Selector Data - edited'!G76 -> 5 | R2: ='Site Selector Data - edited'!G81 -> 4 | T2: =AVERAGE(C2:E2) -> 3.3333333 | U2: =SUM(C2:E2) -> 10
A3: 2 | B3: Boston | C3: ='Site Selector Data - edited'!G7 -> 4 | D3: ='Site Selector Data - edited'!G12 -> 5 | E3: ='Site Selector Data - edited'!G17 -> 5 | F3: ='Site Selector Data - edited'!G22 -> 5 | G3: ='Site Selector Data - edited'!G27 -> 4 | H3: ='Site Selector Data - edited'!G32 -> 2 | I3: ='Site Selector Data - edited'!G37 -> 2 | J3: ='Site Selector Data - edited'!G42 -> 1 | K3: ='Site Selector Data - edited'!G47 -> 2 | L3: ='Site Selector Data - edited'!G52 -> 3 | M3: ='Site Selector Data - edited'!G57 -> 3 | N3: ='Site Selector Data - edited'!G62 -> 3 | O3: ='Site Selector Data - edited'!G67 -> 5 | P3: ='Site Selector Data - edited'!G72 -> 4 | Q3: ='Site Selector Data - edited'!G77 -> 3 | R3: ='Site Selector Data - edited'!G82 -> 2 | T3: =AVERAGE(C3:E3) -> 4.6666667
A4: 3 | B4: Denver | C4: ='Site Selector Data - edited'!G8 -> 1 | D4: ='Site Selector Data - edited'!G13 -> 4 | E4: ='Site Selector Data - edited'!G18 -> 5 | F4: ='Site Selector Data - edited'!G23 -> 4 | G4: ='Site Selector Data - edited'!G28 -> 5 | H4: ='Site Selector Data - edited'!G33 -> 1 | I4: ='Site Selector Data - edited'!G38 -> 4 | J4: ='Site Selector Data - edited'!G43 -> 2 | K4: ='Site Selector Data - edited'!G48 -> 4 | L4: ='Site Selector Data - edited'!G53 -> 4 | M4: ='Site Selector Data - edited'!G58 -> 5 | N4: ='Site Selector Data - edited'!G63 -> 2 | O4: ='Site Selector Data - edited'!G68 -> 2 | P4: ='Site Selector Data - edited'!G73 -> 5 | Q4: ='Site Selector Data - edited'!G78 -> 3 | R4: ='Site Selector Data - edited'!G83 -> 3 | T4: =AVERAGE(C4:E4) -> 3.3333333
A5: 4 | B5: Houston | C5: ='Site Selector Data - edited'!G9 -> 4 | D5: ='Site Selector Data - edited'!G14 -> 3 | E5: ='Site Selector Data - edited'!G19 -> 5 | F5: ='Site Selector Data - edited'!G24 -> 1 | G5: ='Site Selector Data - edited'!G29 -> 2 | H5: ='Site Selector Data - edited'!G34 -> 2 | I5: ='Site Selector Data - edited'!G39 -> 3 | J5: ='Site Selector Data - edited'!G44 -> 4 | K5: ='Site Selector Data - edited'!G49 -> 1 | L5: ='Site Selector Data - edited'!G54 -> 1 | M5: ='Site Selector Data - edited'!G59 -> 5 | N5: ='Site Selector Data - edited'!G64 -> 1 | O5: ='Site Selector Data - edited'!G69 -> 3 | P5: ='Site Selector Data - edited'!G74 -> 1 | Q5: ='Site Selector Data - edited'!G79 -> 5 | R5: ='Site Selector Data - edited'!G84 -> 5 | T5: =AVERAGE(C5:E5) -> 4
A6: 5 | B6: Gainesville | C6: ='Site Selector Data - edited'!G10 -> 3 | D6: ='Site Selector Data - edited'!G15 -> 2 | E6: ='Site Selector Data - edited'!G20 -> 5 | F6: ='Site Selector Data - edited'!G25 -> 2 | G6: ='Site Selector Data - edited'!G30 -> 2 | H6: ='Site Selector Data - edited'!G35 -> 3 | I6: ='Site Selector Data - edited'!G40 -> 1 | J6: ='Site Selector Data - edited'!G45 -> 3 | K6: ='Site Selector Data - edited'!G50 -> 5 | L6: ='Site Selector Data - edited'!G55 -> 5 | M6: ='Site Selector Data - edited'!G60 -> 3 | N6: ='Site Selector Data - edited'!G65 -> 3 | O6: ='Site Selector Data - edited'!G70 -> 4 | P6: ='Site Selector Data - edited'!G75 -> 2 | Q6: ='Site Selector Data - edited'!G80 -> 5 | R6: ='Site Selector Data - edited'!G85 -> 1 | T6: =AVERAGE(C6:E6) -> 3.3333333

Sheet Sources
A1: City | B1: Name | C1: Baseline Water Stress (Regional) | D1: Annual Precipitation (1991-2020) | E1: Recycled Water Infrastructure | F1: Cooling Degree Days (1991-2020) | G1: Annual Mean Relative Humidity | H1: Carbon Regulations | I1: Renewable Energy Mix | J1: Industrial Electricity Rate (2024) | K1: Water & Sewer Cost (Industrial) | L1: Environmental Justice Index | M1: Seismic Hazard (USGS 2023) | N1: Flood Risk Zone | O1: Tornado Frequency (Annual Avg) | P1: Wildfire Hazard | Q1: Winter Weather Disruption | R1: Protected Area Proximity
A2: 1 | B2: Oklahoma City | C2: ='Site Selector Data - edited'!H6 -> https://www.wri.org/applications/aqueduct/water-risk-atlas/ | D2: ='Site Selector Data - edited'!H11 -> https://www.ncei.noaa.gov/products/land-based-station/us-climate-normals | E2: ='Site Selector Data - edited'!H16 -> https://oklahoma.gov/content/dam/ok/en/owrb/documents/water-planning/technical-reports/owrap-fact-sheet.pdf#:~:text=The%20overarching%20goal%20of%20the%20OWRAP%20is,water%20users%20(municipal%2C%20agricultural%2C%20industrial%2C%20and%20others). | F2: ='Site Selector Data - edited'!H21 -> https://www.ncei.noaa.gov/products/land-based-station/us-climate-normals | G2: ='Site Selector Data - edited'!H26 -> https://www.ncei.noaa.gov/products/land-based-station/comparative-climatic-data | H2: ='Site Selector Data - edited'!H31 -> https://oklahoma.gov/deq/divisions/air-quality/rules-planning.html | I2: ='Site Selector Data - edited'!H36 -> https://www.epa.gov/egrid (OK: 41.6% wind+solar+hydro) | J2: ='Site Selector Data - edited'!H41 -> https://www.eia.gov/electricity/sales_revenue_price/ (OK: 5.84¢/kWh) | K2: ='Site Selector Data - edited'!H46 -> https://www.okc.gov/Services/Water-Trash-Recycling/Pay-Bill/Utilities-Rates-Fees | L2: ='Site Selector Data - edited'!H51 -> https://pedp-ejscreen.azurewebsites.net/ | M2: ='Site Selector Data - edited'!H56 -> https://gis.asce.org/beta-7-22/ | N2: ='Site Selector Data - edited'!H61 -> https://www.floodsmart.gov/flood-zones-and-maps/what-is-my-flood-risk | O2: ='Site Selector Data - edited'!H66 -> https://www.weather.gov/oun/tornadodata-ok-monthlyannual | P2: ='Site Selector Data - edited'!H71 -> https://firedanger.cr.usgs.gov/viewer/index.html | Q2: ='Site Selector Data - edited'!H76 -> https://osdh-statewide-risk-assessment-osdh.hub.arcgis.com/pages/winter-storm | R2: ='Site Selector Data - edited'!H81 -> https://www.nps.gov/state/ok/index.htm
A3: 2 | B3: Boston | C3: ='Site Selector Data - edited'!H7 -> https://www.wri.org/applications/aqueduct/water-risk-atlas/ | D3: ='Site Selector Data - edited'!H12 -> https://www.ncei.noaa.gov/products/land-based-station/us-climate-normals | E3: ='Site Selector Data - edited'!H17 -> https://www.mass.gov/info-details/wastewater-reclaimed-water | F3: ='Site Selector Data - edited'!H22 -> https://www.ncei.noaa.gov/products/land-based-station/us-climate-normals | G3: ='Site Selector Data - edited'!H27 -> https://www.ncei.noaa.gov/products/land-based-station/comparative-climatic-data | H3: ='Site Selector Data - edited'!H32 -> https://www.boston.gov/departments/environment/berdo | I3: ='Site Selector Data - edited'!H37 -> https://www.epa.gov/egrid (MA: 18.7% wind+solar+hydro) | J3: ='Site Selector Data - edited'!H42 -> https://www.eia.gov/electricity/sales_revenue_price/ (MA: 18.19¢/kWh) | K3: ='Site Selector Data - edited'!H47 -> https://www.bwsc.org/business-customers/rates | L3: ='Site Selector Data - edited'!H52 -> https://pedp-ejscreen.azurewebsites.net/ | M3: ='Site Selector Data - edited'!H57 -> https://gis.asce.org/beta-7-22/ | N3: ='Site Selector Data - edited'!H62 -> https://www.floodsmart.gov/flood-zones-and-maps/what-is-my-flood-risk | O3: ='Site Selector Data - edited'!H67 -> https://www.tornadopath.com/massachusetts | P3: ='Site Selector Data - edited'!H72 -> https://firedanger.cr.usgs.gov/viewer/index.html | Q3: ='Site Selector Data - edited'!H77 -> https://forecast.weather.gov/product.php?site=BOX&product=CLA&issuedby=BOS | R3: ='Site Selector Data - edited'!H82 -> https://www.nps.gov/state/ma/index.htm
A4: 3 | B4: Denver | C4: ='Site Selector Data - edited'!H8 -> https://www.wri.org/applications/aqueduct/water-risk-atlas/ | D4: ='Site Selector Data - edited'!H13 -> https://www.ncei.noaa.gov/products/land-based-station/us-climate-normals | E4: ='Site Selector Data - edited'!H18 -> https://cwcb.colorado.gov/focus-areas/supply/water-reuse | F4: ='Site Selector Data - edited'!H23 -> https://www.ncei.noaa.gov/products/land-based-station/us-climate-normals | G4: ='Site Selector Data - edited'!H28 -> https://www.ncei.noaa.gov/products/land-based-station/comparative-climatic-data | H4: ='Site Selector Data - edited'!H33 -> https://www.denvergov.org/Government/Agencies-Departments-Offices/Agencies-Departments-Offices-Directory/Climate-Action-Sustainability-and-Resiliency/Cutting-Denvers-Carbon-Pollution/Efficient-Buildings-and-Homes/Denver-Building-Regulations | I4: ='Site Selector Data - edited'!H38 -> https://www.epa.gov/egrid (CO: 34.5% wind+solar+hydro) | J4: ='Site Selector Data - edited'!H43 -> https://www.eia.gov/electricity/sales_revenue_price/ (CO: 8.62¢/kWh) | K4: ='Site Selector Data - edited'!H48 -> https://www.denverwater.org/business/billing-and-rates/2026-rates | L4: ='Site Selector Data - edited'!H53 -> https://pedp-ejscreen.azurewebsites.net/ | M4: ='Site Selector Data - edited'!H58 -> https://gis.asce.org/beta-7-22/ | N4: ='Site Selector Data - edited'!H63 -> https://www.floodsmart.gov/flood-zones-and-maps/what-is-my-flood-risk | O4: ='Site Selector Data - edited'!H68 -> https://www.tornadopath.com/colorado/denver | P4: ='Site Selector Data - edited'!H73 -> https://firedanger.cr.usgs.gov/viewer/index.html | Q4: ='Site Selector Data - edited'!H78 -> https://forecast.weather.gov/product.php?site=BOU&product=CLA&issuedby=DEN | R4: ='Site Selector Data - edited'!H83 -> https://www.nps.gov/state/co/index.htm
A5: 4 | B5: Houston | C5: ='Site Selector Data - edited'!H9 -> https://www.wri.org/applications/aqueduct/water-risk-atlas/ | D5: ='Site Selector Data - edited'!H14 -> https://www.ncei.noaa.gov/products/land-based-station/us-climate-normals | E5: ='Site Selector Data - edited'!H19 -> https://www.twdb.texas.gov/innovativewater/reuse/index.asp | F5: ='Site Selector Data - edited'!H24 -> https://www.ncei.noaa.gov/products/land-based-station/us-climate-normals | G5: ='Site Selector Data - edited'!H29 -> https://www.ncei.noaa.gov/products/land-based-station/comparative-climatic-data | H5: ='Site Selector Data - edited'!H34 -> https://www.houstontx.gov/policies/adminpolicies/3-40.pdf | I5: ='Site Selector Data - edited'!H39 -> https://www.epa.gov/egrid (TX: 26.1% wind+solar+hydro) | J5: ='Site Selector Data - edited'!H44 -> https://www.eia.gov/electricity/sales_revenue_price/ (TX: 6.12¢/kWh) | K5: ='Site Selector Data - edited'!H49 -> https://www.houstonsecured.org/docs/2023_APRIL_WATER_RATES.pdf | L5: ='Site Selector Data - edited'!H54 -> https://pedp-ejscreen.azurewebsites.net/ | M5: ='Site Selector Data - edited'!H59 -> https://gis.asce.org/beta-7-22/ | N5: ='Site Selector Data - edited'!H64 -> https://www.floodsmart.gov/flood-zones-and-maps/what-is-my-flood-risk | O5: ='Site Selector Data - edited'!H69 -> https://www.tornadopath.com/texas/houston | P5: ='Site Selector Data - edited'!H74 -> https://firedanger.cr.usgs.gov/viewer/index.html | Q5: ='Site Selector Data - edited'!H79 -> https://forecast.weather.gov/product.php?site=NWS&product=CLA&issuedby=HOU | R5: ='Site Selector Data - edited'!H84 -> https://www.nps.gov/state/tx/index.htm
A6: 5 | B6: Gainesville | C6: ='Site Selector Data - edited'!H10 -> https://www.wri.org/applications/aqueduct/water-risk-atlas/ | D6: ='Site Selector Data - edited'!H15 -> https://www.ncei.noaa.gov/products/land-based-station/us-climate-normals | E6: ='Site Selector Data - edited'!H20 -> https://floridadep.gov/water/domestic-wastewater/content/water-reuse-program | F6: ='Site Selector Data - edited'!H25 -> https://www.ncei.noaa.gov/products/land-based-station/us-climate-normals | G6: ='Site Selector Data - edited'!H30 -> https://www.ncei.noaa.gov/products/land-based-station/comparative-climatic-data | H6: ='Site Selector Data - edited'!H35 -> https://www.epa.gov/egrid (FL: 786.6 lb/MWh) | I6: ='Site Selector Data - edited'!H40 -> https://www.epa.gov/egrid (FL: 6.7% wind+solar+hydro) | J6: ='Site Selector Data - edited'!H45 -> https://www.eia.gov/electricity/sales_revenue_price/ (FL: 8.50¢/kWh) | K6: ='Site Selector Data - edited'!H50 -> https://www.gainesville.org/DocumentCenter/View/14947/03-2026-Rate-Brochure | L6: ='Site Selector Data - edited'!H55 -> https://pedp-ejscreen.azurewebsites.net/ | M6: ='Site Selector Data - edited'!H60 -> https://gis.asce.org/beta-7-22/ | N6: ='Site Selector Data - edited'!H65 -> https://www.floodsmart.gov/flood-zones-and-maps/what-is-my-flood-risk | O6: ='Site Selector Data - edited'!H70 -> https://www.tornadopath.com/florida/alachua | P6: ='Site Selector Data - edited'!H75 -> https://firedanger.cr.usgs.gov/viewer/index.html | Q6: ='Site Selector Data - edited'!H80 -> https://forecast.weather.gov/product.php?site=JAX&product=CLA&issuedby=JAX | R6: ='Site Selector Data - edited'!H85 -> https://www.nps.gov/state/fl/index.htm

Sheet Scoring Criteria
A1: Sub-Account | B1: Description | C1: Scoring Criteria | D1: Scoring Criteria Description
A2: Baseline Water Stress (Regional) | B2: Regional water withdrawal to availability ratio (WRI framework) | C2: ='Site Selector Data - edited'!J6 -> 5 | D2: ='Site Selector Data - edited'!K6 -> low
C3: ='Site Selector Data - edited'!J7 -> 4 | D3: ='Site Selector Data - edited'!K7 -> low-medium
C4: ='Site Selector Data - edited'!J8 -> 3 | D4: ='Site Selector Data - edited'!K8 -> medium
C5: ='Site Selector Data - edited'!J9 -> 2 | D5: ='Site Selector Data - edited'!K9 -> medium-high
C6: ='Site Selector Data - edited'!J10 -> 1 | D6: ='Site Selector Data - edited'!K10 -> high
A7: Annual Precipitation (1991-2020) | B7: NOAA 30-year climate normal total precipitation | C7: ='Site Selector Data - edited'!J11 -> 5 | D7: ='Site Selector Data - edited'!K11 -> wettest
C8: ='Site Selector Data - edited'!J12 -> 4 | D8: ='Site Selector Data - edited'!K12 -> 0
C9: ='Site Selector Data - edited'!J13 -> 3 | D9: ='Site Selector Data - edited'!K13 -> 0
C10: ='Site Selector Data - edited'!J14 -> 2 | D10: ='Site Selector Data - edited'!K14 -> 0
C11: ='Site Selector Data - edited'!J15 -> 1 | D11: ='Site Selector Data - edited'!K15 -> dryest
A12: Recycled Water Infrastructure | B12: Industrial reclaimed water programs operational | C12: ='Site Selector Data - edited'!J16 -> 5 | D12: ='Site Selector Data - edited'!K16 -> Yes
C13: ='Site Selector Data - edited'!J17 -> 1 | D13: ='Site Selector Data - edited'!K17 -> No
A14: Cooling Degree Days (1991-2020) | B14: Annual cooling demand indicator (base 65°F) | C14: ='Site Selector Data - edited'!J18 -> 0 | D14: ='Site Selector Data - edited'!K18 -> 0
C15: ='Site Selector Data - edited'!J19 -> 0 | D15: ='Site Selector Data - edited'!K19 -> 0
C16: ='Site Selector Data - edited'!J20 -> 0 | D16: ='Site Selector Data - edited'!K20 -> 0
C17: ='Site Selector Data - edited'!J21 -> 5 | D17: ='Site Selector Data - edited'!K21 -> lowest
C18: ='Site Selector Data - edited'!J22 -> 4 | D18: ='Site Selector Data - edited'!K22 -> 0
A19: Annual Mean Relative Humidity | B19: Average RH affects evaporative cooling efficiency | C19: ='Site Selector Data - edited'!J23 -> 3 | D19: ='Site Selector Data - edited'!K23 -> 0
C20: ='Site Selector Data - edited'!J24 -> 2 | D20: ='Site Selector Data - edited'!K24 -> 0
C21: ='Site Selector Data - edited'!J25 -> 1 | D21: ='Site Selector Data - edited'!K25 -> highest
C22: ='Site Selector Data - edited'!J26 -> 5 | D22: ='Site Selector Data - edited'!K26 -> lowest
C23: ='Site Selector Data - edited'!J27 -> 4 | D23: ='Site Selector Data - edited'!K27 -> 0
A24: Carbon Regulations | B24: State regulations on carbon emissions | C24: ='Site Selector Data - edited'!J28 -> 3 | D24: ='Site Selector Data - edited'!K28 -> 0
C25: ='Site Selector Data - edited'!J29 -> 2 | D25: ='Site Selector Data - edited'!K29 -> 0
C26: ='Site Selector Data - edited'!J30 -> 1 | D26: ='Site Selector Data - edited'!K30 -> highest
C27: ='Site Selector Data - edited'!J31 -> 5 | D27: ='Site Selector Data - edited'!K31 -> low
C28: ='Site Selector Data - edited'!J32 -> 4 | D28: ='Site Selector Data - edited'!K32 -> medium-low
A29: Renewable Energy Mix | B29: State renewable generation percentage (wind+solar+hydro) | C29: ='Site Selector Data - edited'!J33 -> 3 | D29: ='Site Selector Data - edited'!K33 -> medium
C30: ='Site Selector Data - edited'!J34 -> 2 | D30: ='Site Selector Data - edited'!K34 -> medium-high
C31: ='Site Selector Data - edited'!J35 -> 1 | D31: ='Site Selector Data - edited'!K35 -> high
C32: ='Site Selector Data - edited'!J36 -> 5 | D32: ='Site Selector Data - edited'!K36 -> highest
C33: ='Site Selector Data - edited'!J37 -> 4 | D33: ='Site Selector Data - edited'!K37 -> 0
A34: Industrial Electricity Rate (2024) | B34: Average industrial electric rate (EIA official data) | C34: ='Site Selector Data - edited'!J38 -> 3 | D34: ='Site Selector Data - edited'!K38 -> 0
C35: ='Site Selector Data - edited'!J39 -> 2 | D35: ='Site Selector Data - edited'!K39 -> 0
C36: ='Site Selector Data - edited'!J40 -> 1 | D36: ='Site Selector Data - edited'!K40 -> lowest
C37: ='Site Selector Data - edited'!J41 -> 5 | D37: ='Site Selector Data - edited'!K41 -> lowest
C38: ='Site Selector Data - edited'!J42 -> 4 | D38: ='Site Selector Data - edited'!K42 -> 0
A39: Water & Sewer Cost (Industrial) | B39: Combined water/sewer cost for large users | C39: ='Site Selector Data - edited'!J43 -> 3 | D39: ='Site Selector Data - edited'!K43 -> 0
C40: ='Site Selector Data - edited'!J44 -> 2 | D40: ='Site Selector Data - edited'!K44 -> 0
...

Sheet Account Weights
A1: Account | B1: Weight
A2: Hydrological & Regulatory Risk | B2: ='Site Selector Data - edited'!A3 -> 0.25
A3: Climate & Operational Physics | B3: ='Site Selector Data - edited'!B3 -> 0.3
A4: Economic & Social Impact | B4: ='Site Selector Data - edited'!C3 -> 0.15
A5: Natural Hazards | B5: ='Site Selector Data - edited'!D3 -> 0.2
A6: Biodiversity | B6: ='Site Selector Data - edited'!E3 -> 0.1

Sheet Scenarios
A1: Scenario | B1: Description | C1: Scoring Criteria | D1: Scoring Criteria Description
A2: Drought | B2: How likely drought is in each place. | C2: ='Site Selector Data - edited'!J87 -> 5 | D2: ='Site Selector Data - edited'!K87 -> low
C3: ='Site Selector Data - edited'!J88 -> 4 | D3: ='Site Selector Data - edited'!K88 -> medium-low
C4: ='Site Selector Data - edited'!J89 -> 3 | D4: ='Site Selector Data - edited'!K89 -> medium
C5: ='Site Selector Data - edited'!J90 -> 2 | D5: ='Site Selector Data - edited'!K90 -> medium-high
C6: ='Site Selector Data - edited'!J91 -> 1 | D6: ='Site Selector Data - edited'!K91 -> high

Sheet Scenario-Drought
A1: City | B1: Value | C1: Score | D1: Source
A2: 1 | B2: ='Site Selector Data - edited'!F87 -> high | C2: ='Site Selector Data - edited'!G87 -> 1 | D2: ='Site Selector Data - edited'!H87 -> https://www.cpc.ncep.noaa.gov/products/expert_assessment/sdo_summary.php#:~:text=Despite%20an%20increasingly%20wet%20time,forecast%20to%20remain%20drought%2Dfree.
A3: 2 | B3: ='Site Selector Data - edited'!F88 -> medium | C3: ='Site Selector Data - edited'!G88 -> 3 | D3: ='Site Selector Data - edited'!H88 -> https://www.cpc.ncep.noaa.gov/products/expert_assessment/sdo_summary.php#:~:text=Despite%20an%20increasingly%20wet%20time,forecast%20to%20remain%20drought%2Dfree.
A4: 3 | B4: ='Site Selector Data - edited'!F89 -> high | C4: ='Site Selector Data - edited'!G89 -> 1 | D4: ='Site Selector Data - edited'!H89 -> https://www.cpc.ncep.noaa.gov/products/expert_assessment/sdo_summary.php#:~:text=Despite%20an%20increasingly%20wet%20time,forecast%20to%20remain%20drought%2Dfree.
A5: 4 | B5: ='Site Selector Data - edited'!F90 -> medium-high | C5: ='Site Selector Data - edited'!G90 -> 2 | D5: ='Site Selector Data - edited'!H90 -> https://www.cpc.ncep.noaa.gov/products/expert_assessment/sdo_summary.php#:~:text=Despite%20an%20increasingly%20wet%20time,forecast%20to%20remain%20drought%2Dfree.
A6: 5 | B6: ='Site Selector Data - edited'!F91 -> medium-high | C6: ='Site Selector Data - edited'!G91 -> 2 | D6: ='Site Selector Data - edited'!H91 -> https://www.cpc.ncep.noaa.gov/products/expert_assessment/sdo_summary.php#:~:text=Despite%20an%20increasingly%20wet%20time,forecast%20to%20remain%20drought%2Dfree.
